
2022-08-20 13:04:47,047 INFO: errors [in C:\Users\Larry\ALX_FULLSTACK\Fyyur\FSND\projects\01_fyyur\starter_code\app.py:911]
2022-08-20 13:06:00,358 ERROR: Exception on /venues [GET] [in C:\Users\Larry\anaconda3\lib\site-packages\flask\app.py:1891]
Traceback (most recent call last):
  File "C:\Users\Larry\anaconda3\lib\site-packages\sqlalchemy\engine\base.py", line 1771, in _execute_context
    self.dialect.do_execute(
  File "C:\Users\Larry\anaconda3\lib\site-packages\sqlalchemy\engine\default.py", line 717, in do_execute
    cursor.execute(statement, parameters)
sqlite3.OperationalError: no such table: Venue

The above exception was the direct cause of the following exception:

Traceback (most recent call last):
  File "C:\Users\Larry\anaconda3\lib\site-packages\flask\app.py", line 2447, in wsgi_app
    response = self.full_dispatch_request()
  File "C:\Users\Larry\anaconda3\lib\site-packages\flask\app.py", line 1952, in full_dispatch_request
    rv = self.handle_user_exception(e)
  File "C:\Users\Larry\anaconda3\lib\site-packages\flask\app.py", line 1821, in handle_user_exception
    reraise(exc_type, exc_value, tb)
  File "C:\Users\Larry\anaconda3\lib\site-packages\flask\_compat.py", line 39, in reraise
    raise value
  File "C:\Users\Larry\anaconda3\lib\site-packages\flask\app.py", line 1950, in full_dispatch_request
    rv = self.dispatch_request()
  File "C:\Users\Larry\anaconda3\lib\site-packages\flask\app.py", line 1936, in dispatch_request
    return self.view_functions[rule.endpoint](**req.view_args)
  File "C:\Users\Larry\ALX_FULLSTACK\Fyyur\FSND\projects\01_fyyur\starter_code\app.py", line 257, in venues
    venue_state_and_city = ''
  File "C:\Users\Larry\anaconda3\lib\site-packages\sqlalchemy\orm\query.py", line 2712, in all
    return self._iter().all()
  File "C:\Users\Larry\anaconda3\lib\site-packages\sqlalchemy\orm\query.py", line 2847, in _iter
    result = self.session.execute(
  File "C:\Users\Larry\anaconda3\lib\site-packages\sqlalchemy\orm\session.py", line 1689, in execute
    result = conn._execute_20(statement, params or {}, execution_options)
  File "C:\Users\Larry\anaconda3\lib\site-packages\sqlalchemy\engine\base.py", line 1583, in _execute_20
    return meth(self, args_10style, kwargs_10style, execution_options)
  File "C:\Users\Larry\anaconda3\lib\site-packages\sqlalchemy\sql\elements.py", line 323, in _execute_on_connection
    return connection._execute_clauseelement(
  File "C:\Users\Larry\anaconda3\lib\site-packages\sqlalchemy\engine\base.py", line 1452, in _execute_clauseelement
    ret = self._execute_context(
  File "C:\Users\Larry\anaconda3\lib\site-packages\sqlalchemy\engine\base.py", line 1814, in _execute_context
    self._handle_dbapi_exception(
  File "C:\Users\Larry\anaconda3\lib\site-packages\sqlalchemy\engine\base.py", line 1995, in _handle_dbapi_exception
    util.raise_(
  File "C:\Users\Larry\anaconda3\lib\site-packages\sqlalchemy\util\compat.py", line 207, in raise_
    raise exception
  File "C:\Users\Larry\anaconda3\lib\site-packages\sqlalchemy\engine\base.py", line 1771, in _execute_context
    self.dialect.do_execute(
  File "C:\Users\Larry\anaconda3\lib\site-packages\sqlalchemy\engine\default.py", line 717, in do_execute
    cursor.execute(statement, parameters)
sqlalchemy.exc.OperationalError: (sqlite3.OperationalError) no such table: Venue
[SQL: SELECT "Venue".id AS "Venue_id", "Venue".name AS "Venue_name", "Venue".city AS "Venue_city", "Venue".state AS "Venue_state", "Venue".address AS "Venue_address", "Venue".phone AS "Venue_phone", "Venue".image_link AS "Venue_image_link", "Venue".facebook_link AS "Venue_facebook_link", "Venue".description AS "Venue_description", "Venue".seeking_talent AS "Venue_seeking_talent", "Venue".website AS "Venue_website", "Venue".genres AS "Venue_genres" 
FROM "Venue" GROUP BY "Venue".id, "Venue".state, "Venue".city]
(Background on this error at: https://sqlalche.me/e/14/e3q8)
2022-08-20 13:06:03,372 ERROR: Exception on /artists [GET] [in C:\Users\Larry\anaconda3\lib\site-packages\flask\app.py:1891]
Traceback (most recent call last):
  File "C:\Users\Larry\anaconda3\lib\site-packages\sqlalchemy\engine\base.py", line 1771, in _execute_context
    self.dialect.do_execute(
  File "C:\Users\Larry\anaconda3\lib\site-packages\sqlalchemy\engine\default.py", line 717, in do_execute
    cursor.execute(statement, parameters)
sqlite3.OperationalError: no such table: Artist

The above exception was the direct cause of the following exception:

Traceback (most recent call last):
  File "C:\Users\Larry\anaconda3\lib\site-packages\flask\app.py", line 2447, in wsgi_app
    response = self.full_dispatch_request()
  File "C:\Users\Larry\anaconda3\lib\site-packages\flask\app.py", line 1952, in full_dispatch_request
    rv = self.handle_user_exception(e)
  File "C:\Users\Larry\anaconda3\lib\site-packages\flask\app.py", line 1821, in handle_user_exception
    reraise(exc_type, exc_value, tb)
  File "C:\Users\Larry\anaconda3\lib\site-packages\flask\_compat.py", line 39, in reraise
    raise value
  File "C:\Users\Larry\anaconda3\lib\site-packages\flask\app.py", line 1950, in full_dispatch_request
    rv = self.dispatch_request()
  File "C:\Users\Larry\anaconda3\lib\site-packages\flask\app.py", line 1936, in dispatch_request
    return self.view_functions[rule.endpoint](**req.view_args)
  File "C:\Users\Larry\ALX_FULLSTACK\Fyyur\FSND\projects\01_fyyur\starter_code\app.py", line 496, in artists
  File "C:\Users\Larry\anaconda3\lib\site-packages\sqlalchemy\orm\query.py", line 2712, in all
    return self._iter().all()
  File "C:\Users\Larry\anaconda3\lib\site-packages\sqlalchemy\orm\query.py", line 2847, in _iter
    result = self.session.execute(
  File "C:\Users\Larry\anaconda3\lib\site-packages\sqlalchemy\orm\session.py", line 1689, in execute
    result = conn._execute_20(statement, params or {}, execution_options)
  File "C:\Users\Larry\anaconda3\lib\site-packages\sqlalchemy\engine\base.py", line 1583, in _execute_20
    return meth(self, args_10style, kwargs_10style, execution_options)
  File "C:\Users\Larry\anaconda3\lib\site-packages\sqlalchemy\sql\elements.py", line 323, in _execute_on_connection
    return connection._execute_clauseelement(
  File "C:\Users\Larry\anaconda3\lib\site-packages\sqlalchemy\engine\base.py", line 1452, in _execute_clauseelement
    ret = self._execute_context(
  File "C:\Users\Larry\anaconda3\lib\site-packages\sqlalchemy\engine\base.py", line 1814, in _execute_context
    self._handle_dbapi_exception(
  File "C:\Users\Larry\anaconda3\lib\site-packages\sqlalchemy\engine\base.py", line 1995, in _handle_dbapi_exception
    util.raise_(
  File "C:\Users\Larry\anaconda3\lib\site-packages\sqlalchemy\util\compat.py", line 207, in raise_
    raise exception
  File "C:\Users\Larry\anaconda3\lib\site-packages\sqlalchemy\engine\base.py", line 1771, in _execute_context
    self.dialect.do_execute(
  File "C:\Users\Larry\anaconda3\lib\site-packages\sqlalchemy\engine\default.py", line 717, in do_execute
    cursor.execute(statement, parameters)
sqlalchemy.exc.OperationalError: (sqlite3.OperationalError) no such table: Artist
[SQL: SELECT "Artist".id AS "Artist_id", "Artist".name AS "Artist_name", "Artist".city AS "Artist_city", "Artist".state AS "Artist_state", "Artist".phone AS "Artist_phone", "Artist".genres AS "Artist_genres", "Artist".image_link AS "Artist_image_link", "Artist".facebook_link AS "Artist_facebook_link", "Artist".website AS "Artist_website", "Artist".seeking_talent AS "Artist_seeking_talent", "Artist".seeking_description AS "Artist_seeking_description" 
FROM "Artist"]
(Background on this error at: https://sqlalche.me/e/14/e3q8)
2022-08-20 13:06:51,822 ERROR: Exception on /venues [GET] [in C:\Users\Larry\anaconda3\lib\site-packages\flask\app.py:1891]
Traceback (most recent call last):
  File "C:\Users\Larry\anaconda3\lib\site-packages\sqlalchemy\engine\base.py", line 1771, in _execute_context
    self.dialect.do_execute(
  File "C:\Users\Larry\anaconda3\lib\site-packages\sqlalchemy\engine\default.py", line 717, in do_execute
    cursor.execute(statement, parameters)
sqlite3.OperationalError: no such table: Venue

The above exception was the direct cause of the following exception:

Traceback (most recent call last):
  File "C:\Users\Larry\anaconda3\lib\site-packages\flask\app.py", line 2447, in wsgi_app
    response = self.full_dispatch_request()
  File "C:\Users\Larry\anaconda3\lib\site-packages\flask\app.py", line 1952, in full_dispatch_request
    rv = self.handle_user_exception(e)
  File "C:\Users\Larry\anaconda3\lib\site-packages\flask\app.py", line 1821, in handle_user_exception
    reraise(exc_type, exc_value, tb)
  File "C:\Users\Larry\anaconda3\lib\site-packages\flask\_compat.py", line 39, in reraise
    raise value
  File "C:\Users\Larry\anaconda3\lib\site-packages\flask\app.py", line 1950, in full_dispatch_request
    rv = self.dispatch_request()
  File "C:\Users\Larry\anaconda3\lib\site-packages\flask\app.py", line 1936, in dispatch_request
    return self.view_functions[rule.endpoint](**req.view_args)
  File "C:\Users\Larry\ALX_FULLSTACK\Fyyur\FSND\projects\01_fyyur\starter_code\app.py", line 257, in venues
    venue_state_and_city = ''
  File "C:\Users\Larry\anaconda3\lib\site-packages\sqlalchemy\orm\query.py", line 2712, in all
    return self._iter().all()
  File "C:\Users\Larry\anaconda3\lib\site-packages\sqlalchemy\orm\query.py", line 2847, in _iter
    result = self.session.execute(
  File "C:\Users\Larry\anaconda3\lib\site-packages\sqlalchemy\orm\session.py", line 1689, in execute
    result = conn._execute_20(statement, params or {}, execution_options)
  File "C:\Users\Larry\anaconda3\lib\site-packages\sqlalchemy\engine\base.py", line 1583, in _execute_20
    return meth(self, args_10style, kwargs_10style, execution_options)
  File "C:\Users\Larry\anaconda3\lib\site-packages\sqlalchemy\sql\elements.py", line 323, in _execute_on_connection
    return connection._execute_clauseelement(
  File "C:\Users\Larry\anaconda3\lib\site-packages\sqlalchemy\engine\base.py", line 1452, in _execute_clauseelement
    ret = self._execute_context(
  File "C:\Users\Larry\anaconda3\lib\site-packages\sqlalchemy\engine\base.py", line 1814, in _execute_context
    self._handle_dbapi_exception(
  File "C:\Users\Larry\anaconda3\lib\site-packages\sqlalchemy\engine\base.py", line 1995, in _handle_dbapi_exception
    util.raise_(
  File "C:\Users\Larry\anaconda3\lib\site-packages\sqlalchemy\util\compat.py", line 207, in raise_
    raise exception
  File "C:\Users\Larry\anaconda3\lib\site-packages\sqlalchemy\engine\base.py", line 1771, in _execute_context
    self.dialect.do_execute(
  File "C:\Users\Larry\anaconda3\lib\site-packages\sqlalchemy\engine\default.py", line 717, in do_execute
    cursor.execute(statement, parameters)
sqlalchemy.exc.OperationalError: (sqlite3.OperationalError) no such table: Venue
[SQL: SELECT "Venue".id AS "Venue_id", "Venue".name AS "Venue_name", "Venue".city AS "Venue_city", "Venue".state AS "Venue_state", "Venue".address AS "Venue_address", "Venue".phone AS "Venue_phone", "Venue".image_link AS "Venue_image_link", "Venue".facebook_link AS "Venue_facebook_link", "Venue".description AS "Venue_description", "Venue".seeking_talent AS "Venue_seeking_talent", "Venue".website AS "Venue_website", "Venue".genres AS "Venue_genres" 
FROM "Venue" GROUP BY "Venue".id, "Venue".state, "Venue".city]
(Background on this error at: https://sqlalche.me/e/14/e3q8)
2022-08-20 13:07:17,383 ERROR: Exception on /venues [GET] [in C:\Users\Larry\anaconda3\lib\site-packages\flask\app.py:1891]
Traceback (most recent call last):
  File "C:\Users\Larry\anaconda3\lib\site-packages\sqlalchemy\engine\base.py", line 1771, in _execute_context
    self.dialect.do_execute(
  File "C:\Users\Larry\anaconda3\lib\site-packages\sqlalchemy\engine\default.py", line 717, in do_execute
    cursor.execute(statement, parameters)
sqlite3.OperationalError: no such table: Venue

The above exception was the direct cause of the following exception:

Traceback (most recent call last):
  File "C:\Users\Larry\anaconda3\lib\site-packages\flask\app.py", line 2447, in wsgi_app
    response = self.full_dispatch_request()
  File "C:\Users\Larry\anaconda3\lib\site-packages\flask\app.py", line 1952, in full_dispatch_request
    rv = self.handle_user_exception(e)
  File "C:\Users\Larry\anaconda3\lib\site-packages\flask\app.py", line 1821, in handle_user_exception
    reraise(exc_type, exc_value, tb)
  File "C:\Users\Larry\anaconda3\lib\site-packages\flask\_compat.py", line 39, in reraise
    raise value
  File "C:\Users\Larry\anaconda3\lib\site-packages\flask\app.py", line 1950, in full_dispatch_request
    rv = self.dispatch_request()
  File "C:\Users\Larry\anaconda3\lib\site-packages\flask\app.py", line 1936, in dispatch_request
    return self.view_functions[rule.endpoint](**req.view_args)
  File "C:\Users\Larry\ALX_FULLSTACK\Fyyur\FSND\projects\01_fyyur\starter_code\app.py", line 257, in venues
    venues = Venue.query.group_by(Venue.id, Venue.state, Venue.city).all()
  File "C:\Users\Larry\anaconda3\lib\site-packages\sqlalchemy\orm\query.py", line 2712, in all
    return self._iter().all()
  File "C:\Users\Larry\anaconda3\lib\site-packages\sqlalchemy\orm\query.py", line 2847, in _iter
    result = self.session.execute(
  File "C:\Users\Larry\anaconda3\lib\site-packages\sqlalchemy\orm\session.py", line 1689, in execute
    result = conn._execute_20(statement, params or {}, execution_options)
  File "C:\Users\Larry\anaconda3\lib\site-packages\sqlalchemy\engine\base.py", line 1583, in _execute_20
    return meth(self, args_10style, kwargs_10style, execution_options)
  File "C:\Users\Larry\anaconda3\lib\site-packages\sqlalchemy\sql\elements.py", line 323, in _execute_on_connection
    return connection._execute_clauseelement(
  File "C:\Users\Larry\anaconda3\lib\site-packages\sqlalchemy\engine\base.py", line 1452, in _execute_clauseelement
    ret = self._execute_context(
  File "C:\Users\Larry\anaconda3\lib\site-packages\sqlalchemy\engine\base.py", line 1814, in _execute_context
    self._handle_dbapi_exception(
  File "C:\Users\Larry\anaconda3\lib\site-packages\sqlalchemy\engine\base.py", line 1995, in _handle_dbapi_exception
    util.raise_(
  File "C:\Users\Larry\anaconda3\lib\site-packages\sqlalchemy\util\compat.py", line 207, in raise_
    raise exception
  File "C:\Users\Larry\anaconda3\lib\site-packages\sqlalchemy\engine\base.py", line 1771, in _execute_context
    self.dialect.do_execute(
  File "C:\Users\Larry\anaconda3\lib\site-packages\sqlalchemy\engine\default.py", line 717, in do_execute
    cursor.execute(statement, parameters)
sqlalchemy.exc.OperationalError: (sqlite3.OperationalError) no such table: Venue
[SQL: SELECT "Venue".id AS "Venue_id", "Venue".name AS "Venue_name", "Venue".city AS "Venue_city", "Venue".state AS "Venue_state", "Venue".address AS "Venue_address", "Venue".phone AS "Venue_phone", "Venue".image_link AS "Venue_image_link", "Venue".facebook_link AS "Venue_facebook_link", "Venue".description AS "Venue_description", "Venue".seeking_talent AS "Venue_seeking_talent", "Venue".website AS "Venue_website", "Venue".genres AS "Venue_genres" 
FROM "Venue" GROUP BY "Venue".id, "Venue".state, "Venue".city]
(Background on this error at: https://sqlalche.me/e/14/e3q8)
2022-08-20 13:07:23,414 ERROR: Exception on /artists [GET] [in C:\Users\Larry\anaconda3\lib\site-packages\flask\app.py:1891]
Traceback (most recent call last):
  File "C:\Users\Larry\anaconda3\lib\site-packages\sqlalchemy\engine\base.py", line 1771, in _execute_context
    self.dialect.do_execute(
  File "C:\Users\Larry\anaconda3\lib\site-packages\sqlalchemy\engine\default.py", line 717, in do_execute
    cursor.execute(statement, parameters)
sqlite3.OperationalError: no such table: Artist

The above exception was the direct cause of the following exception:

Traceback (most recent call last):
  File "C:\Users\Larry\anaconda3\lib\site-packages\flask\app.py", line 2447, in wsgi_app
    response = self.full_dispatch_request()
  File "C:\Users\Larry\anaconda3\lib\site-packages\flask\app.py", line 1952, in full_dispatch_request
    rv = self.handle_user_exception(e)
  File "C:\Users\Larry\anaconda3\lib\site-packages\flask\app.py", line 1821, in handle_user_exception
    reraise(exc_type, exc_value, tb)
  File "C:\Users\Larry\anaconda3\lib\site-packages\flask\_compat.py", line 39, in reraise
    raise value
  File "C:\Users\Larry\anaconda3\lib\site-packages\flask\app.py", line 1950, in full_dispatch_request
    rv = self.dispatch_request()
  File "C:\Users\Larry\anaconda3\lib\site-packages\flask\app.py", line 1936, in dispatch_request
    return self.view_functions[rule.endpoint](**req.view_args)
  File "C:\Users\Larry\ALX_FULLSTACK\Fyyur\FSND\projects\01_fyyur\starter_code\app.py", line 496, in artists
    data = Artist.query.all()
  File "C:\Users\Larry\anaconda3\lib\site-packages\sqlalchemy\orm\query.py", line 2712, in all
    return self._iter().all()
  File "C:\Users\Larry\anaconda3\lib\site-packages\sqlalchemy\orm\query.py", line 2847, in _iter
    result = self.session.execute(
  File "C:\Users\Larry\anaconda3\lib\site-packages\sqlalchemy\orm\session.py", line 1689, in execute
    result = conn._execute_20(statement, params or {}, execution_options)
  File "C:\Users\Larry\anaconda3\lib\site-packages\sqlalchemy\engine\base.py", line 1583, in _execute_20
    return meth(self, args_10style, kwargs_10style, execution_options)
  File "C:\Users\Larry\anaconda3\lib\site-packages\sqlalchemy\sql\elements.py", line 323, in _execute_on_connection
    return connection._execute_clauseelement(
  File "C:\Users\Larry\anaconda3\lib\site-packages\sqlalchemy\engine\base.py", line 1452, in _execute_clauseelement
    ret = self._execute_context(
  File "C:\Users\Larry\anaconda3\lib\site-packages\sqlalchemy\engine\base.py", line 1814, in _execute_context
    self._handle_dbapi_exception(
  File "C:\Users\Larry\anaconda3\lib\site-packages\sqlalchemy\engine\base.py", line 1995, in _handle_dbapi_exception
    util.raise_(
  File "C:\Users\Larry\anaconda3\lib\site-packages\sqlalchemy\util\compat.py", line 207, in raise_
    raise exception
  File "C:\Users\Larry\anaconda3\lib\site-packages\sqlalchemy\engine\base.py", line 1771, in _execute_context
    self.dialect.do_execute(
  File "C:\Users\Larry\anaconda3\lib\site-packages\sqlalchemy\engine\default.py", line 717, in do_execute
    cursor.execute(statement, parameters)
sqlalchemy.exc.OperationalError: (sqlite3.OperationalError) no such table: Artist
[SQL: SELECT "Artist".id AS "Artist_id", "Artist".name AS "Artist_name", "Artist".city AS "Artist_city", "Artist".state AS "Artist_state", "Artist".phone AS "Artist_phone", "Artist".genres AS "Artist_genres", "Artist".image_link AS "Artist_image_link", "Artist".facebook_link AS "Artist_facebook_link", "Artist".website AS "Artist_website", "Artist".seeking_talent AS "Artist_seeking_talent", "Artist".seeking_description AS "Artist_seeking_description" 
FROM "Artist"]
(Background on this error at: https://sqlalche.me/e/14/e3q8)
2022-08-20 13:09:39,020 ERROR: Exception on /venues [GET] [in C:\Users\Larry\anaconda3\lib\site-packages\flask\app.py:1891]
Traceback (most recent call last):
  File "C:\Users\Larry\anaconda3\lib\site-packages\sqlalchemy\engine\base.py", line 1771, in _execute_context
    self.dialect.do_execute(
  File "C:\Users\Larry\anaconda3\lib\site-packages\sqlalchemy\engine\default.py", line 717, in do_execute
    cursor.execute(statement, parameters)
sqlite3.OperationalError: no such table: Venue

The above exception was the direct cause of the following exception:

Traceback (most recent call last):
  File "C:\Users\Larry\anaconda3\lib\site-packages\flask\app.py", line 2447, in wsgi_app
    response = self.full_dispatch_request()
  File "C:\Users\Larry\anaconda3\lib\site-packages\flask\app.py", line 1952, in full_dispatch_request
    rv = self.handle_user_exception(e)
  File "C:\Users\Larry\anaconda3\lib\site-packages\flask\app.py", line 1821, in handle_user_exception
    reraise(exc_type, exc_value, tb)
  File "C:\Users\Larry\anaconda3\lib\site-packages\flask\_compat.py", line 39, in reraise
    raise value
  File "C:\Users\Larry\anaconda3\lib\site-packages\flask\app.py", line 1950, in full_dispatch_request
    rv = self.dispatch_request()
  File "C:\Users\Larry\anaconda3\lib\site-packages\flask\app.py", line 1936, in dispatch_request
    return self.view_functions[rule.endpoint](**req.view_args)
  File "C:\Users\Larry\ALX_FULLSTACK\Fyyur\FSND\projects\01_fyyur\starter_code\app.py", line 257, in venues
    print(venue)
  File "C:\Users\Larry\anaconda3\lib\site-packages\sqlalchemy\orm\query.py", line 2712, in all
    return self._iter().all()
  File "C:\Users\Larry\anaconda3\lib\site-packages\sqlalchemy\orm\query.py", line 2847, in _iter
    result = self.session.execute(
  File "C:\Users\Larry\anaconda3\lib\site-packages\sqlalchemy\orm\session.py", line 1689, in execute
    result = conn._execute_20(statement, params or {}, execution_options)
  File "C:\Users\Larry\anaconda3\lib\site-packages\sqlalchemy\engine\base.py", line 1583, in _execute_20
    return meth(self, args_10style, kwargs_10style, execution_options)
  File "C:\Users\Larry\anaconda3\lib\site-packages\sqlalchemy\sql\elements.py", line 323, in _execute_on_connection
    return connection._execute_clauseelement(
  File "C:\Users\Larry\anaconda3\lib\site-packages\sqlalchemy\engine\base.py", line 1452, in _execute_clauseelement
    ret = self._execute_context(
  File "C:\Users\Larry\anaconda3\lib\site-packages\sqlalchemy\engine\base.py", line 1814, in _execute_context
    self._handle_dbapi_exception(
  File "C:\Users\Larry\anaconda3\lib\site-packages\sqlalchemy\engine\base.py", line 1995, in _handle_dbapi_exception
    util.raise_(
  File "C:\Users\Larry\anaconda3\lib\site-packages\sqlalchemy\util\compat.py", line 207, in raise_
    raise exception
  File "C:\Users\Larry\anaconda3\lib\site-packages\sqlalchemy\engine\base.py", line 1771, in _execute_context
    self.dialect.do_execute(
  File "C:\Users\Larry\anaconda3\lib\site-packages\sqlalchemy\engine\default.py", line 717, in do_execute
    cursor.execute(statement, parameters)
sqlalchemy.exc.OperationalError: (sqlite3.OperationalError) no such table: Venue
[SQL: SELECT "Venue".id AS "Venue_id", "Venue".name AS "Venue_name", "Venue".city AS "Venue_city", "Venue".state AS "Venue_state", "Venue".address AS "Venue_address", "Venue".phone AS "Venue_phone", "Venue".image_link AS "Venue_image_link", "Venue".facebook_link AS "Venue_facebook_link", "Venue".description AS "Venue_description", "Venue".seeking_talent AS "Venue_seeking_talent", "Venue".website AS "Venue_website", "Venue".genres AS "Venue_genres" 
FROM "Venue" GROUP BY "Venue".id, "Venue".state, "Venue".city]
(Background on this error at: https://sqlalche.me/e/14/e3q8)
2022-08-20 13:09:41,967 ERROR: Exception on /venues [GET] [in C:\Users\Larry\anaconda3\lib\site-packages\flask\app.py:1891]
Traceback (most recent call last):
  File "C:\Users\Larry\anaconda3\lib\site-packages\sqlalchemy\engine\base.py", line 1771, in _execute_context
    self.dialect.do_execute(
  File "C:\Users\Larry\anaconda3\lib\site-packages\sqlalchemy\engine\default.py", line 717, in do_execute
    cursor.execute(statement, parameters)
sqlite3.OperationalError: no such table: Venue

The above exception was the direct cause of the following exception:

Traceback (most recent call last):
  File "C:\Users\Larry\anaconda3\lib\site-packages\flask\app.py", line 2447, in wsgi_app
    response = self.full_dispatch_request()
  File "C:\Users\Larry\anaconda3\lib\site-packages\flask\app.py", line 1952, in full_dispatch_request
    rv = self.handle_user_exception(e)
  File "C:\Users\Larry\anaconda3\lib\site-packages\flask\app.py", line 1821, in handle_user_exception
    reraise(exc_type, exc_value, tb)
  File "C:\Users\Larry\anaconda3\lib\site-packages\flask\_compat.py", line 39, in reraise
    raise value
  File "C:\Users\Larry\anaconda3\lib\site-packages\flask\app.py", line 1950, in full_dispatch_request
    rv = self.dispatch_request()
  File "C:\Users\Larry\anaconda3\lib\site-packages\flask\app.py", line 1936, in dispatch_request
    return self.view_functions[rule.endpoint](**req.view_args)
  File "C:\Users\Larry\ALX_FULLSTACK\Fyyur\FSND\projects\01_fyyur\starter_code\app.py", line 257, in venues
    print(venue)
  File "C:\Users\Larry\anaconda3\lib\site-packages\sqlalchemy\orm\query.py", line 2712, in all
    return self._iter().all()
  File "C:\Users\Larry\anaconda3\lib\site-packages\sqlalchemy\orm\query.py", line 2847, in _iter
    result = self.session.execute(
  File "C:\Users\Larry\anaconda3\lib\site-packages\sqlalchemy\orm\session.py", line 1689, in execute
    result = conn._execute_20(statement, params or {}, execution_options)
  File "C:\Users\Larry\anaconda3\lib\site-packages\sqlalchemy\engine\base.py", line 1583, in _execute_20
    return meth(self, args_10style, kwargs_10style, execution_options)
  File "C:\Users\Larry\anaconda3\lib\site-packages\sqlalchemy\sql\elements.py", line 323, in _execute_on_connection
    return connection._execute_clauseelement(
  File "C:\Users\Larry\anaconda3\lib\site-packages\sqlalchemy\engine\base.py", line 1452, in _execute_clauseelement
    ret = self._execute_context(
  File "C:\Users\Larry\anaconda3\lib\site-packages\sqlalchemy\engine\base.py", line 1814, in _execute_context
    self._handle_dbapi_exception(
  File "C:\Users\Larry\anaconda3\lib\site-packages\sqlalchemy\engine\base.py", line 1995, in _handle_dbapi_exception
    util.raise_(
  File "C:\Users\Larry\anaconda3\lib\site-packages\sqlalchemy\util\compat.py", line 207, in raise_
    raise exception
  File "C:\Users\Larry\anaconda3\lib\site-packages\sqlalchemy\engine\base.py", line 1771, in _execute_context
    self.dialect.do_execute(
  File "C:\Users\Larry\anaconda3\lib\site-packages\sqlalchemy\engine\default.py", line 717, in do_execute
    cursor.execute(statement, parameters)
sqlalchemy.exc.OperationalError: (sqlite3.OperationalError) no such table: Venue
[SQL: SELECT "Venue".id AS "Venue_id", "Venue".name AS "Venue_name", "Venue".city AS "Venue_city", "Venue".state AS "Venue_state", "Venue".address AS "Venue_address", "Venue".phone AS "Venue_phone", "Venue".image_link AS "Venue_image_link", "Venue".facebook_link AS "Venue_facebook_link", "Venue".description AS "Venue_description", "Venue".seeking_talent AS "Venue_seeking_talent", "Venue".website AS "Venue_website", "Venue".genres AS "Venue_genres" 
FROM "Venue" GROUP BY "Venue".id, "Venue".state, "Venue".city]
(Background on this error at: https://sqlalche.me/e/14/e3q8)
2022-08-20 13:09:47,712 ERROR: Exception on /artists [GET] [in C:\Users\Larry\anaconda3\lib\site-packages\flask\app.py:1891]
Traceback (most recent call last):
  File "C:\Users\Larry\anaconda3\lib\site-packages\sqlalchemy\engine\base.py", line 1771, in _execute_context
    self.dialect.do_execute(
  File "C:\Users\Larry\anaconda3\lib\site-packages\sqlalchemy\engine\default.py", line 717, in do_execute
    cursor.execute(statement, parameters)
sqlite3.OperationalError: no such table: Artist

The above exception was the direct cause of the following exception:

Traceback (most recent call last):
  File "C:\Users\Larry\anaconda3\lib\site-packages\flask\app.py", line 2447, in wsgi_app
    response = self.full_dispatch_request()
  File "C:\Users\Larry\anaconda3\lib\site-packages\flask\app.py", line 1952, in full_dispatch_request
    rv = self.handle_user_exception(e)
  File "C:\Users\Larry\anaconda3\lib\site-packages\flask\app.py", line 1821, in handle_user_exception
    reraise(exc_type, exc_value, tb)
  File "C:\Users\Larry\anaconda3\lib\site-packages\flask\_compat.py", line 39, in reraise
    raise value
  File "C:\Users\Larry\anaconda3\lib\site-packages\flask\app.py", line 1950, in full_dispatch_request
    rv = self.dispatch_request()
  File "C:\Users\Larry\anaconda3\lib\site-packages\flask\app.py", line 1936, in dispatch_request
    return self.view_functions[rule.endpoint](**req.view_args)
  File "C:\Users\Larry\ALX_FULLSTACK\Fyyur\FSND\projects\01_fyyur\starter_code\app.py", line 496, in artists
    "id": 5,
  File "C:\Users\Larry\anaconda3\lib\site-packages\sqlalchemy\orm\query.py", line 2712, in all
    return self._iter().all()
  File "C:\Users\Larry\anaconda3\lib\site-packages\sqlalchemy\orm\query.py", line 2847, in _iter
    result = self.session.execute(
  File "C:\Users\Larry\anaconda3\lib\site-packages\sqlalchemy\orm\session.py", line 1689, in execute
    result = conn._execute_20(statement, params or {}, execution_options)
  File "C:\Users\Larry\anaconda3\lib\site-packages\sqlalchemy\engine\base.py", line 1583, in _execute_20
    return meth(self, args_10style, kwargs_10style, execution_options)
  File "C:\Users\Larry\anaconda3\lib\site-packages\sqlalchemy\sql\elements.py", line 323, in _execute_on_connection
    return connection._execute_clauseelement(
  File "C:\Users\Larry\anaconda3\lib\site-packages\sqlalchemy\engine\base.py", line 1452, in _execute_clauseelement
    ret = self._execute_context(
  File "C:\Users\Larry\anaconda3\lib\site-packages\sqlalchemy\engine\base.py", line 1814, in _execute_context
    self._handle_dbapi_exception(
  File "C:\Users\Larry\anaconda3\lib\site-packages\sqlalchemy\engine\base.py", line 1995, in _handle_dbapi_exception
    util.raise_(
  File "C:\Users\Larry\anaconda3\lib\site-packages\sqlalchemy\util\compat.py", line 207, in raise_
    raise exception
  File "C:\Users\Larry\anaconda3\lib\site-packages\sqlalchemy\engine\base.py", line 1771, in _execute_context
    self.dialect.do_execute(
  File "C:\Users\Larry\anaconda3\lib\site-packages\sqlalchemy\engine\default.py", line 717, in do_execute
    cursor.execute(statement, parameters)
sqlalchemy.exc.OperationalError: (sqlite3.OperationalError) no such table: Artist
[SQL: SELECT "Artist".id AS "Artist_id", "Artist".name AS "Artist_name", "Artist".city AS "Artist_city", "Artist".state AS "Artist_state", "Artist".phone AS "Artist_phone", "Artist".genres AS "Artist_genres", "Artist".image_link AS "Artist_image_link", "Artist".facebook_link AS "Artist_facebook_link", "Artist".website AS "Artist_website", "Artist".seeking_talent AS "Artist_seeking_talent", "Artist".seeking_description AS "Artist_seeking_description" 
FROM "Artist"]
(Background on this error at: https://sqlalche.me/e/14/e3q8)
2022-08-20 13:12:29,016 ERROR: Exception on /artists [GET] [in C:\Users\Larry\anaconda3\lib\site-packages\flask\app.py:1891]
Traceback (most recent call last):
  File "C:\Users\Larry\anaconda3\lib\site-packages\sqlalchemy\engine\base.py", line 1771, in _execute_context
    self.dialect.do_execute(
  File "C:\Users\Larry\anaconda3\lib\site-packages\sqlalchemy\engine\default.py", line 717, in do_execute
    cursor.execute(statement, parameters)
sqlite3.OperationalError: no such table: Artist

The above exception was the direct cause of the following exception:

Traceback (most recent call last):
  File "C:\Users\Larry\anaconda3\lib\site-packages\flask\app.py", line 2447, in wsgi_app
    response = self.full_dispatch_request()
  File "C:\Users\Larry\anaconda3\lib\site-packages\flask\app.py", line 1952, in full_dispatch_request
    rv = self.handle_user_exception(e)
  File "C:\Users\Larry\anaconda3\lib\site-packages\flask\app.py", line 1821, in handle_user_exception
    reraise(exc_type, exc_value, tb)
  File "C:\Users\Larry\anaconda3\lib\site-packages\flask\_compat.py", line 39, in reraise
    raise value
  File "C:\Users\Larry\anaconda3\lib\site-packages\flask\app.py", line 1950, in full_dispatch_request
    rv = self.dispatch_request()
  File "C:\Users\Larry\anaconda3\lib\site-packages\flask\app.py", line 1936, in dispatch_request
    return self.view_functions[rule.endpoint](**req.view_args)
  File "C:\Users\Larry\ALX_FULLSTACK\Fyyur\FSND\projects\01_fyyur\starter_code\app.py", line 496, in artists
    "id": 5,
  File "C:\Users\Larry\anaconda3\lib\site-packages\sqlalchemy\orm\query.py", line 2712, in all
    return self._iter().all()
  File "C:\Users\Larry\anaconda3\lib\site-packages\sqlalchemy\orm\query.py", line 2847, in _iter
    result = self.session.execute(
  File "C:\Users\Larry\anaconda3\lib\site-packages\sqlalchemy\orm\session.py", line 1689, in execute
    result = conn._execute_20(statement, params or {}, execution_options)
  File "C:\Users\Larry\anaconda3\lib\site-packages\sqlalchemy\engine\base.py", line 1583, in _execute_20
    return meth(self, args_10style, kwargs_10style, execution_options)
  File "C:\Users\Larry\anaconda3\lib\site-packages\sqlalchemy\sql\elements.py", line 323, in _execute_on_connection
    return connection._execute_clauseelement(
  File "C:\Users\Larry\anaconda3\lib\site-packages\sqlalchemy\engine\base.py", line 1452, in _execute_clauseelement
    ret = self._execute_context(
  File "C:\Users\Larry\anaconda3\lib\site-packages\sqlalchemy\engine\base.py", line 1814, in _execute_context
    self._handle_dbapi_exception(
  File "C:\Users\Larry\anaconda3\lib\site-packages\sqlalchemy\engine\base.py", line 1995, in _handle_dbapi_exception
    util.raise_(
  File "C:\Users\Larry\anaconda3\lib\site-packages\sqlalchemy\util\compat.py", line 207, in raise_
    raise exception
  File "C:\Users\Larry\anaconda3\lib\site-packages\sqlalchemy\engine\base.py", line 1771, in _execute_context
    self.dialect.do_execute(
  File "C:\Users\Larry\anaconda3\lib\site-packages\sqlalchemy\engine\default.py", line 717, in do_execute
    cursor.execute(statement, parameters)
sqlalchemy.exc.OperationalError: (sqlite3.OperationalError) no such table: Artist
[SQL: SELECT "Artist".id AS "Artist_id", "Artist".name AS "Artist_name", "Artist".city AS "Artist_city", "Artist".state AS "Artist_state", "Artist".phone AS "Artist_phone", "Artist".genres AS "Artist_genres", "Artist".image_link AS "Artist_image_link", "Artist".facebook_link AS "Artist_facebook_link", "Artist".website AS "Artist_website", "Artist".seeking_talent AS "Artist_seeking_talent", "Artist".seeking_description AS "Artist_seeking_description" 
FROM "Artist"]
(Background on this error at: https://sqlalche.me/e/14/e3q8)
2022-08-20 13:28:12,647 INFO: errors [in c:\Users\Larry\ALX_FULLSTACK\Fyyur\FSND\projects\01_fyyur\starter_code\app.py:911]
2022-08-20 13:28:21,610 ERROR: Exception on /venues [GET] [in C:\Users\Larry\anaconda3\lib\site-packages\flask\app.py:1891]
Traceback (most recent call last):
  File "C:\Users\Larry\anaconda3\lib\site-packages\sqlalchemy\engine\base.py", line 1771, in _execute_context
    self.dialect.do_execute(
  File "C:\Users\Larry\anaconda3\lib\site-packages\sqlalchemy\engine\default.py", line 717, in do_execute
    cursor.execute(statement, parameters)
sqlite3.OperationalError: no such table: Venue

The above exception was the direct cause of the following exception:

Traceback (most recent call last):
  File "C:\Users\Larry\anaconda3\lib\site-packages\flask\app.py", line 2447, in wsgi_app
    response = self.full_dispatch_request()
  File "C:\Users\Larry\anaconda3\lib\site-packages\flask\app.py", line 1952, in full_dispatch_request
    rv = self.handle_user_exception(e)
  File "C:\Users\Larry\anaconda3\lib\site-packages\flask\app.py", line 1821, in handle_user_exception
    reraise(exc_type, exc_value, tb)
  File "C:\Users\Larry\anaconda3\lib\site-packages\flask\_compat.py", line 39, in reraise
    raise value
  File "C:\Users\Larry\anaconda3\lib\site-packages\flask\app.py", line 1950, in full_dispatch_request
    rv = self.dispatch_request()
  File "C:\Users\Larry\anaconda3\lib\site-packages\flask\app.py", line 1936, in dispatch_request
    return self.view_functions[rule.endpoint](**req.view_args)
  File "C:\Users\Larry\ALX_FULLSTACK\Fyyur\FSND\projects\01_fyyur\starter_code\app.py", line 257, in venues
    venues = Venue.query.group_by(Venue.id, Venue.state, Venue.city).all()
  File "C:\Users\Larry\anaconda3\lib\site-packages\sqlalchemy\orm\query.py", line 2712, in all
    return self._iter().all()
  File "C:\Users\Larry\anaconda3\lib\site-packages\sqlalchemy\orm\query.py", line 2847, in _iter
    result = self.session.execute(
  File "C:\Users\Larry\anaconda3\lib\site-packages\sqlalchemy\orm\session.py", line 1689, in execute
    result = conn._execute_20(statement, params or {}, execution_options)
  File "C:\Users\Larry\anaconda3\lib\site-packages\sqlalchemy\engine\base.py", line 1583, in _execute_20
    return meth(self, args_10style, kwargs_10style, execution_options)
  File "C:\Users\Larry\anaconda3\lib\site-packages\sqlalchemy\sql\elements.py", line 323, in _execute_on_connection
    return connection._execute_clauseelement(
  File "C:\Users\Larry\anaconda3\lib\site-packages\sqlalchemy\engine\base.py", line 1452, in _execute_clauseelement
    ret = self._execute_context(
  File "C:\Users\Larry\anaconda3\lib\site-packages\sqlalchemy\engine\base.py", line 1814, in _execute_context
    self._handle_dbapi_exception(
  File "C:\Users\Larry\anaconda3\lib\site-packages\sqlalchemy\engine\base.py", line 1995, in _handle_dbapi_exception
    util.raise_(
  File "C:\Users\Larry\anaconda3\lib\site-packages\sqlalchemy\util\compat.py", line 207, in raise_
    raise exception
  File "C:\Users\Larry\anaconda3\lib\site-packages\sqlalchemy\engine\base.py", line 1771, in _execute_context
    self.dialect.do_execute(
  File "C:\Users\Larry\anaconda3\lib\site-packages\sqlalchemy\engine\default.py", line 717, in do_execute
    cursor.execute(statement, parameters)
sqlalchemy.exc.OperationalError: (sqlite3.OperationalError) no such table: Venue
[SQL: SELECT "Venue".id AS "Venue_id", "Venue".name AS "Venue_name", "Venue".city AS "Venue_city", "Venue".state AS "Venue_state", "Venue".address AS "Venue_address", "Venue".phone AS "Venue_phone", "Venue".image_link AS "Venue_image_link", "Venue".facebook_link AS "Venue_facebook_link", "Venue".description AS "Venue_description", "Venue".seeking_talent AS "Venue_seeking_talent", "Venue".website AS "Venue_website", "Venue".genres AS "Venue_genres" 
FROM "Venue" GROUP BY "Venue".id, "Venue".state, "Venue".city]
(Background on this error at: https://sqlalche.me/e/14/e3q8)
2022-08-20 13:28:25,033 ERROR: Exception on /artists [GET] [in C:\Users\Larry\anaconda3\lib\site-packages\flask\app.py:1891]
Traceback (most recent call last):
  File "C:\Users\Larry\anaconda3\lib\site-packages\sqlalchemy\engine\base.py", line 1771, in _execute_context
    self.dialect.do_execute(
  File "C:\Users\Larry\anaconda3\lib\site-packages\sqlalchemy\engine\default.py", line 717, in do_execute
    cursor.execute(statement, parameters)
sqlite3.OperationalError: no such table: Artist

The above exception was the direct cause of the following exception:

Traceback (most recent call last):
  File "C:\Users\Larry\anaconda3\lib\site-packages\flask\app.py", line 2447, in wsgi_app
    response = self.full_dispatch_request()
  File "C:\Users\Larry\anaconda3\lib\site-packages\flask\app.py", line 1952, in full_dispatch_request
    rv = self.handle_user_exception(e)
  File "C:\Users\Larry\anaconda3\lib\site-packages\flask\app.py", line 1821, in handle_user_exception
    reraise(exc_type, exc_value, tb)
  File "C:\Users\Larry\anaconda3\lib\site-packages\flask\_compat.py", line 39, in reraise
    raise value
  File "C:\Users\Larry\anaconda3\lib\site-packages\flask\app.py", line 1950, in full_dispatch_request
    rv = self.dispatch_request()
  File "C:\Users\Larry\anaconda3\lib\site-packages\flask\app.py", line 1936, in dispatch_request
    return self.view_functions[rule.endpoint](**req.view_args)
  File "C:\Users\Larry\ALX_FULLSTACK\Fyyur\FSND\projects\01_fyyur\starter_code\app.py", line 496, in artists
    data = Artist.query.all()
  File "C:\Users\Larry\anaconda3\lib\site-packages\sqlalchemy\orm\query.py", line 2712, in all
    return self._iter().all()
  File "C:\Users\Larry\anaconda3\lib\site-packages\sqlalchemy\orm\query.py", line 2847, in _iter
    result = self.session.execute(
  File "C:\Users\Larry\anaconda3\lib\site-packages\sqlalchemy\orm\session.py", line 1689, in execute
    result = conn._execute_20(statement, params or {}, execution_options)
  File "C:\Users\Larry\anaconda3\lib\site-packages\sqlalchemy\engine\base.py", line 1583, in _execute_20
    return meth(self, args_10style, kwargs_10style, execution_options)
  File "C:\Users\Larry\anaconda3\lib\site-packages\sqlalchemy\sql\elements.py", line 323, in _execute_on_connection
    return connection._execute_clauseelement(
  File "C:\Users\Larry\anaconda3\lib\site-packages\sqlalchemy\engine\base.py", line 1452, in _execute_clauseelement
    ret = self._execute_context(
  File "C:\Users\Larry\anaconda3\lib\site-packages\sqlalchemy\engine\base.py", line 1814, in _execute_context
    self._handle_dbapi_exception(
  File "C:\Users\Larry\anaconda3\lib\site-packages\sqlalchemy\engine\base.py", line 1995, in _handle_dbapi_exception
    util.raise_(
  File "C:\Users\Larry\anaconda3\lib\site-packages\sqlalchemy\util\compat.py", line 207, in raise_
    raise exception
  File "C:\Users\Larry\anaconda3\lib\site-packages\sqlalchemy\engine\base.py", line 1771, in _execute_context
    self.dialect.do_execute(
  File "C:\Users\Larry\anaconda3\lib\site-packages\sqlalchemy\engine\default.py", line 717, in do_execute
    cursor.execute(statement, parameters)
sqlalchemy.exc.OperationalError: (sqlite3.OperationalError) no such table: Artist
[SQL: SELECT "Artist".id AS "Artist_id", "Artist".name AS "Artist_name", "Artist".city AS "Artist_city", "Artist".state AS "Artist_state", "Artist".phone AS "Artist_phone", "Artist".genres AS "Artist_genres", "Artist".image_link AS "Artist_image_link", "Artist".facebook_link AS "Artist_facebook_link", "Artist".website AS "Artist_website", "Artist".seeking_talent AS "Artist_seeking_talent", "Artist".seeking_description AS "Artist_seeking_description" 
FROM "Artist"]
(Background on this error at: https://sqlalche.me/e/14/e3q8)
2022-08-20 13:28:33,358 ERROR: Exception on /venues [GET] [in C:\Users\Larry\anaconda3\lib\site-packages\flask\app.py:1891]
Traceback (most recent call last):
  File "C:\Users\Larry\anaconda3\lib\site-packages\sqlalchemy\engine\base.py", line 1771, in _execute_context
    self.dialect.do_execute(
  File "C:\Users\Larry\anaconda3\lib\site-packages\sqlalchemy\engine\default.py", line 717, in do_execute
    cursor.execute(statement, parameters)
sqlite3.OperationalError: no such table: Venue

The above exception was the direct cause of the following exception:

Traceback (most recent call last):
  File "C:\Users\Larry\anaconda3\lib\site-packages\flask\app.py", line 2447, in wsgi_app
    response = self.full_dispatch_request()
  File "C:\Users\Larry\anaconda3\lib\site-packages\flask\app.py", line 1952, in full_dispatch_request
    rv = self.handle_user_exception(e)
  File "C:\Users\Larry\anaconda3\lib\site-packages\flask\app.py", line 1821, in handle_user_exception
    reraise(exc_type, exc_value, tb)
  File "C:\Users\Larry\anaconda3\lib\site-packages\flask\_compat.py", line 39, in reraise
    raise value
  File "C:\Users\Larry\anaconda3\lib\site-packages\flask\app.py", line 1950, in full_dispatch_request
    rv = self.dispatch_request()
  File "C:\Users\Larry\anaconda3\lib\site-packages\flask\app.py", line 1936, in dispatch_request
    return self.view_functions[rule.endpoint](**req.view_args)
  File "C:\Users\Larry\ALX_FULLSTACK\Fyyur\FSND\projects\01_fyyur\starter_code\app.py", line 257, in venues
    venues = Venue.query.group_by(Venue.id, Venue.state, Venue.city).all()
  File "C:\Users\Larry\anaconda3\lib\site-packages\sqlalchemy\orm\query.py", line 2712, in all
    return self._iter().all()
  File "C:\Users\Larry\anaconda3\lib\site-packages\sqlalchemy\orm\query.py", line 2847, in _iter
    result = self.session.execute(
  File "C:\Users\Larry\anaconda3\lib\site-packages\sqlalchemy\orm\session.py", line 1689, in execute
    result = conn._execute_20(statement, params or {}, execution_options)
  File "C:\Users\Larry\anaconda3\lib\site-packages\sqlalchemy\engine\base.py", line 1583, in _execute_20
    return meth(self, args_10style, kwargs_10style, execution_options)
  File "C:\Users\Larry\anaconda3\lib\site-packages\sqlalchemy\sql\elements.py", line 323, in _execute_on_connection
    return connection._execute_clauseelement(
  File "C:\Users\Larry\anaconda3\lib\site-packages\sqlalchemy\engine\base.py", line 1452, in _execute_clauseelement
    ret = self._execute_context(
  File "C:\Users\Larry\anaconda3\lib\site-packages\sqlalchemy\engine\base.py", line 1814, in _execute_context
    self._handle_dbapi_exception(
  File "C:\Users\Larry\anaconda3\lib\site-packages\sqlalchemy\engine\base.py", line 1995, in _handle_dbapi_exception
    util.raise_(
  File "C:\Users\Larry\anaconda3\lib\site-packages\sqlalchemy\util\compat.py", line 207, in raise_
    raise exception
  File "C:\Users\Larry\anaconda3\lib\site-packages\sqlalchemy\engine\base.py", line 1771, in _execute_context
    self.dialect.do_execute(
  File "C:\Users\Larry\anaconda3\lib\site-packages\sqlalchemy\engine\default.py", line 717, in do_execute
    cursor.execute(statement, parameters)
sqlalchemy.exc.OperationalError: (sqlite3.OperationalError) no such table: Venue
[SQL: SELECT "Venue".id AS "Venue_id", "Venue".name AS "Venue_name", "Venue".city AS "Venue_city", "Venue".state AS "Venue_state", "Venue".address AS "Venue_address", "Venue".phone AS "Venue_phone", "Venue".image_link AS "Venue_image_link", "Venue".facebook_link AS "Venue_facebook_link", "Venue".description AS "Venue_description", "Venue".seeking_talent AS "Venue_seeking_talent", "Venue".website AS "Venue_website", "Venue".genres AS "Venue_genres" 
FROM "Venue" GROUP BY "Venue".id, "Venue".state, "Venue".city]
(Background on this error at: https://sqlalche.me/e/14/e3q8)
2022-08-20 13:28:47,223 ERROR: Exception on /artists [GET] [in C:\Users\Larry\anaconda3\lib\site-packages\flask\app.py:1891]
Traceback (most recent call last):
  File "C:\Users\Larry\anaconda3\lib\site-packages\sqlalchemy\engine\base.py", line 1771, in _execute_context
    self.dialect.do_execute(
  File "C:\Users\Larry\anaconda3\lib\site-packages\sqlalchemy\engine\default.py", line 717, in do_execute
    cursor.execute(statement, parameters)
sqlite3.OperationalError: no such table: Artist

The above exception was the direct cause of the following exception:

Traceback (most recent call last):
  File "C:\Users\Larry\anaconda3\lib\site-packages\flask\app.py", line 2447, in wsgi_app
    response = self.full_dispatch_request()
  File "C:\Users\Larry\anaconda3\lib\site-packages\flask\app.py", line 1952, in full_dispatch_request
    rv = self.handle_user_exception(e)
  File "C:\Users\Larry\anaconda3\lib\site-packages\flask\app.py", line 1821, in handle_user_exception
    reraise(exc_type, exc_value, tb)
  File "C:\Users\Larry\anaconda3\lib\site-packages\flask\_compat.py", line 39, in reraise
    raise value
  File "C:\Users\Larry\anaconda3\lib\site-packages\flask\app.py", line 1950, in full_dispatch_request
    rv = self.dispatch_request()
  File "C:\Users\Larry\anaconda3\lib\site-packages\flask\app.py", line 1936, in dispatch_request
    return self.view_functions[rule.endpoint](**req.view_args)
  File "C:\Users\Larry\ALX_FULLSTACK\Fyyur\FSND\projects\01_fyyur\starter_code\app.py", line 496, in artists
    data = Artist.query.all()
  File "C:\Users\Larry\anaconda3\lib\site-packages\sqlalchemy\orm\query.py", line 2712, in all
    return self._iter().all()
  File "C:\Users\Larry\anaconda3\lib\site-packages\sqlalchemy\orm\query.py", line 2847, in _iter
    result = self.session.execute(
  File "C:\Users\Larry\anaconda3\lib\site-packages\sqlalchemy\orm\session.py", line 1689, in execute
    result = conn._execute_20(statement, params or {}, execution_options)
  File "C:\Users\Larry\anaconda3\lib\site-packages\sqlalchemy\engine\base.py", line 1583, in _execute_20
    return meth(self, args_10style, kwargs_10style, execution_options)
  File "C:\Users\Larry\anaconda3\lib\site-packages\sqlalchemy\sql\elements.py", line 323, in _execute_on_connection
    return connection._execute_clauseelement(
  File "C:\Users\Larry\anaconda3\lib\site-packages\sqlalchemy\engine\base.py", line 1452, in _execute_clauseelement
    ret = self._execute_context(
  File "C:\Users\Larry\anaconda3\lib\site-packages\sqlalchemy\engine\base.py", line 1814, in _execute_context
    self._handle_dbapi_exception(
  File "C:\Users\Larry\anaconda3\lib\site-packages\sqlalchemy\engine\base.py", line 1995, in _handle_dbapi_exception
    util.raise_(
  File "C:\Users\Larry\anaconda3\lib\site-packages\sqlalchemy\util\compat.py", line 207, in raise_
    raise exception
  File "C:\Users\Larry\anaconda3\lib\site-packages\sqlalchemy\engine\base.py", line 1771, in _execute_context
    self.dialect.do_execute(
  File "C:\Users\Larry\anaconda3\lib\site-packages\sqlalchemy\engine\default.py", line 717, in do_execute
    cursor.execute(statement, parameters)
sqlalchemy.exc.OperationalError: (sqlite3.OperationalError) no such table: Artist
[SQL: SELECT "Artist".id AS "Artist_id", "Artist".name AS "Artist_name", "Artist".city AS "Artist_city", "Artist".state AS "Artist_state", "Artist".phone AS "Artist_phone", "Artist".genres AS "Artist_genres", "Artist".image_link AS "Artist_image_link", "Artist".facebook_link AS "Artist_facebook_link", "Artist".website AS "Artist_website", "Artist".seeking_talent AS "Artist_seeking_talent", "Artist".seeking_description AS "Artist_seeking_description" 
FROM "Artist"]
(Background on this error at: https://sqlalche.me/e/14/e3q8)
2022-08-20 13:30:06,375 ERROR: Exception on /artists [GET] [in C:\Users\Larry\anaconda3\lib\site-packages\flask\app.py:1891]
Traceback (most recent call last):
  File "C:\Users\Larry\anaconda3\lib\site-packages\sqlalchemy\engine\base.py", line 1771, in _execute_context
    self.dialect.do_execute(
  File "C:\Users\Larry\anaconda3\lib\site-packages\sqlalchemy\engine\default.py", line 717, in do_execute
    cursor.execute(statement, parameters)
sqlite3.OperationalError: no such table: Artist

The above exception was the direct cause of the following exception:

Traceback (most recent call last):
  File "C:\Users\Larry\anaconda3\lib\site-packages\flask\app.py", line 2447, in wsgi_app
    response = self.full_dispatch_request()
  File "C:\Users\Larry\anaconda3\lib\site-packages\flask\app.py", line 1952, in full_dispatch_request
    rv = self.handle_user_exception(e)
  File "C:\Users\Larry\anaconda3\lib\site-packages\flask\app.py", line 1821, in handle_user_exception
    reraise(exc_type, exc_value, tb)
  File "C:\Users\Larry\anaconda3\lib\site-packages\flask\_compat.py", line 39, in reraise
    raise value
  File "C:\Users\Larry\anaconda3\lib\site-packages\flask\app.py", line 1950, in full_dispatch_request
    rv = self.dispatch_request()
  File "C:\Users\Larry\anaconda3\lib\site-packages\flask\app.py", line 1936, in dispatch_request
    return self.view_functions[rule.endpoint](**req.view_args)
  File "C:\Users\Larry\ALX_FULLSTACK\Fyyur\FSND\projects\01_fyyur\starter_code\app.py", line 496, in artists
    "id": 5,
  File "C:\Users\Larry\anaconda3\lib\site-packages\sqlalchemy\orm\query.py", line 2712, in all
    return self._iter().all()
  File "C:\Users\Larry\anaconda3\lib\site-packages\sqlalchemy\orm\query.py", line 2847, in _iter
    result = self.session.execute(
  File "C:\Users\Larry\anaconda3\lib\site-packages\sqlalchemy\orm\session.py", line 1689, in execute
    result = conn._execute_20(statement, params or {}, execution_options)
  File "C:\Users\Larry\anaconda3\lib\site-packages\sqlalchemy\engine\base.py", line 1583, in _execute_20
    return meth(self, args_10style, kwargs_10style, execution_options)
  File "C:\Users\Larry\anaconda3\lib\site-packages\sqlalchemy\sql\elements.py", line 323, in _execute_on_connection
    return connection._execute_clauseelement(
  File "C:\Users\Larry\anaconda3\lib\site-packages\sqlalchemy\engine\base.py", line 1452, in _execute_clauseelement
    ret = self._execute_context(
  File "C:\Users\Larry\anaconda3\lib\site-packages\sqlalchemy\engine\base.py", line 1814, in _execute_context
    self._handle_dbapi_exception(
  File "C:\Users\Larry\anaconda3\lib\site-packages\sqlalchemy\engine\base.py", line 1995, in _handle_dbapi_exception
    util.raise_(
  File "C:\Users\Larry\anaconda3\lib\site-packages\sqlalchemy\util\compat.py", line 207, in raise_
    raise exception
  File "C:\Users\Larry\anaconda3\lib\site-packages\sqlalchemy\engine\base.py", line 1771, in _execute_context
    self.dialect.do_execute(
  File "C:\Users\Larry\anaconda3\lib\site-packages\sqlalchemy\engine\default.py", line 717, in do_execute
    cursor.execute(statement, parameters)
sqlalchemy.exc.OperationalError: (sqlite3.OperationalError) no such table: Artist
[SQL: SELECT "Artist".id AS "Artist_id", "Artist".name AS "Artist_name", "Artist".city AS "Artist_city", "Artist".state AS "Artist_state", "Artist".phone AS "Artist_phone", "Artist".genres AS "Artist_genres", "Artist".image_link AS "Artist_image_link", "Artist".facebook_link AS "Artist_facebook_link", "Artist".website AS "Artist_website", "Artist".seeking_talent AS "Artist_seeking_talent", "Artist".seeking_description AS "Artist_seeking_description" 
FROM "Artist"]
(Background on this error at: https://sqlalche.me/e/14/e3q8)
2022-08-20 13:30:12,263 ERROR: Exception on /artists [GET] [in C:\Users\Larry\anaconda3\lib\site-packages\flask\app.py:1891]
Traceback (most recent call last):
  File "C:\Users\Larry\anaconda3\lib\site-packages\sqlalchemy\engine\base.py", line 1771, in _execute_context
    self.dialect.do_execute(
  File "C:\Users\Larry\anaconda3\lib\site-packages\sqlalchemy\engine\default.py", line 717, in do_execute
    cursor.execute(statement, parameters)
sqlite3.OperationalError: no such table: Artist

The above exception was the direct cause of the following exception:

Traceback (most recent call last):
  File "C:\Users\Larry\anaconda3\lib\site-packages\flask\app.py", line 2447, in wsgi_app
    response = self.full_dispatch_request()
  File "C:\Users\Larry\anaconda3\lib\site-packages\flask\app.py", line 1952, in full_dispatch_request
    rv = self.handle_user_exception(e)
  File "C:\Users\Larry\anaconda3\lib\site-packages\flask\app.py", line 1821, in handle_user_exception
    reraise(exc_type, exc_value, tb)
  File "C:\Users\Larry\anaconda3\lib\site-packages\flask\_compat.py", line 39, in reraise
    raise value
  File "C:\Users\Larry\anaconda3\lib\site-packages\flask\app.py", line 1950, in full_dispatch_request
    rv = self.dispatch_request()
  File "C:\Users\Larry\anaconda3\lib\site-packages\flask\app.py", line 1936, in dispatch_request
    return self.view_functions[rule.endpoint](**req.view_args)
  File "C:\Users\Larry\ALX_FULLSTACK\Fyyur\FSND\projects\01_fyyur\starter_code\app.py", line 496, in artists
    "id": 5,
  File "C:\Users\Larry\anaconda3\lib\site-packages\sqlalchemy\orm\query.py", line 2712, in all
    return self._iter().all()
  File "C:\Users\Larry\anaconda3\lib\site-packages\sqlalchemy\orm\query.py", line 2847, in _iter
    result = self.session.execute(
  File "C:\Users\Larry\anaconda3\lib\site-packages\sqlalchemy\orm\session.py", line 1689, in execute
    result = conn._execute_20(statement, params or {}, execution_options)
  File "C:\Users\Larry\anaconda3\lib\site-packages\sqlalchemy\engine\base.py", line 1583, in _execute_20
    return meth(self, args_10style, kwargs_10style, execution_options)
  File "C:\Users\Larry\anaconda3\lib\site-packages\sqlalchemy\sql\elements.py", line 323, in _execute_on_connection
    return connection._execute_clauseelement(
  File "C:\Users\Larry\anaconda3\lib\site-packages\sqlalchemy\engine\base.py", line 1452, in _execute_clauseelement
    ret = self._execute_context(
  File "C:\Users\Larry\anaconda3\lib\site-packages\sqlalchemy\engine\base.py", line 1814, in _execute_context
    self._handle_dbapi_exception(
  File "C:\Users\Larry\anaconda3\lib\site-packages\sqlalchemy\engine\base.py", line 1995, in _handle_dbapi_exception
    util.raise_(
  File "C:\Users\Larry\anaconda3\lib\site-packages\sqlalchemy\util\compat.py", line 207, in raise_
    raise exception
  File "C:\Users\Larry\anaconda3\lib\site-packages\sqlalchemy\engine\base.py", line 1771, in _execute_context
    self.dialect.do_execute(
  File "C:\Users\Larry\anaconda3\lib\site-packages\sqlalchemy\engine\default.py", line 717, in do_execute
    cursor.execute(statement, parameters)
sqlalchemy.exc.OperationalError: (sqlite3.OperationalError) no such table: Artist
[SQL: SELECT "Artist".id AS "Artist_id", "Artist".name AS "Artist_name", "Artist".city AS "Artist_city", "Artist".state AS "Artist_state", "Artist".phone AS "Artist_phone", "Artist".genres AS "Artist_genres", "Artist".image_link AS "Artist_image_link", "Artist".facebook_link AS "Artist_facebook_link", "Artist".website AS "Artist_website", "Artist".seeking_talent AS "Artist_seeking_talent", "Artist".seeking_description AS "Artist_seeking_description" 
FROM "Artist"]
(Background on this error at: https://sqlalche.me/e/14/e3q8)
2022-08-20 13:30:16,551 ERROR: Exception on /venues [GET] [in C:\Users\Larry\anaconda3\lib\site-packages\flask\app.py:1891]
Traceback (most recent call last):
  File "C:\Users\Larry\anaconda3\lib\site-packages\sqlalchemy\engine\base.py", line 1771, in _execute_context
    self.dialect.do_execute(
  File "C:\Users\Larry\anaconda3\lib\site-packages\sqlalchemy\engine\default.py", line 717, in do_execute
    cursor.execute(statement, parameters)
sqlite3.OperationalError: no such table: Venue

The above exception was the direct cause of the following exception:

Traceback (most recent call last):
  File "C:\Users\Larry\anaconda3\lib\site-packages\flask\app.py", line 2447, in wsgi_app
    response = self.full_dispatch_request()
  File "C:\Users\Larry\anaconda3\lib\site-packages\flask\app.py", line 1952, in full_dispatch_request
    rv = self.handle_user_exception(e)
  File "C:\Users\Larry\anaconda3\lib\site-packages\flask\app.py", line 1821, in handle_user_exception
    reraise(exc_type, exc_value, tb)
  File "C:\Users\Larry\anaconda3\lib\site-packages\flask\_compat.py", line 39, in reraise
    raise value
  File "C:\Users\Larry\anaconda3\lib\site-packages\flask\app.py", line 1950, in full_dispatch_request
    rv = self.dispatch_request()
  File "C:\Users\Larry\anaconda3\lib\site-packages\flask\app.py", line 1936, in dispatch_request
    return self.view_functions[rule.endpoint](**req.view_args)
  File "C:\Users\Larry\ALX_FULLSTACK\Fyyur\FSND\projects\01_fyyur\starter_code\app.py", line 257, in venues
    print(venue)
  File "C:\Users\Larry\anaconda3\lib\site-packages\sqlalchemy\orm\query.py", line 2712, in all
    return self._iter().all()
  File "C:\Users\Larry\anaconda3\lib\site-packages\sqlalchemy\orm\query.py", line 2847, in _iter
    result = self.session.execute(
  File "C:\Users\Larry\anaconda3\lib\site-packages\sqlalchemy\orm\session.py", line 1689, in execute
    result = conn._execute_20(statement, params or {}, execution_options)
  File "C:\Users\Larry\anaconda3\lib\site-packages\sqlalchemy\engine\base.py", line 1583, in _execute_20
    return meth(self, args_10style, kwargs_10style, execution_options)
  File "C:\Users\Larry\anaconda3\lib\site-packages\sqlalchemy\sql\elements.py", line 323, in _execute_on_connection
    return connection._execute_clauseelement(
  File "C:\Users\Larry\anaconda3\lib\site-packages\sqlalchemy\engine\base.py", line 1452, in _execute_clauseelement
    ret = self._execute_context(
  File "C:\Users\Larry\anaconda3\lib\site-packages\sqlalchemy\engine\base.py", line 1814, in _execute_context
    self._handle_dbapi_exception(
  File "C:\Users\Larry\anaconda3\lib\site-packages\sqlalchemy\engine\base.py", line 1995, in _handle_dbapi_exception
    util.raise_(
  File "C:\Users\Larry\anaconda3\lib\site-packages\sqlalchemy\util\compat.py", line 207, in raise_
    raise exception
  File "C:\Users\Larry\anaconda3\lib\site-packages\sqlalchemy\engine\base.py", line 1771, in _execute_context
    self.dialect.do_execute(
  File "C:\Users\Larry\anaconda3\lib\site-packages\sqlalchemy\engine\default.py", line 717, in do_execute
    cursor.execute(statement, parameters)
sqlalchemy.exc.OperationalError: (sqlite3.OperationalError) no such table: Venue
[SQL: SELECT "Venue".id AS "Venue_id", "Venue".name AS "Venue_name", "Venue".city AS "Venue_city", "Venue".state AS "Venue_state", "Venue".address AS "Venue_address", "Venue".phone AS "Venue_phone", "Venue".image_link AS "Venue_image_link", "Venue".facebook_link AS "Venue_facebook_link", "Venue".description AS "Venue_description", "Venue".seeking_talent AS "Venue_seeking_talent", "Venue".website AS "Venue_website", "Venue".genres AS "Venue_genres" 
FROM "Venue" GROUP BY "Venue".id, "Venue".state, "Venue".city]
(Background on this error at: https://sqlalche.me/e/14/e3q8)
2022-08-20 13:37:35,185 ERROR: Exception on /venues [GET] [in C:\Users\Larry\anaconda3\lib\site-packages\flask\app.py:1891]
Traceback (most recent call last):
  File "C:\Users\Larry\anaconda3\lib\site-packages\sqlalchemy\engine\base.py", line 1771, in _execute_context
    self.dialect.do_execute(
  File "C:\Users\Larry\anaconda3\lib\site-packages\sqlalchemy\engine\default.py", line 717, in do_execute
    cursor.execute(statement, parameters)
sqlite3.OperationalError: no such table: Venue

The above exception was the direct cause of the following exception:

Traceback (most recent call last):
  File "C:\Users\Larry\anaconda3\lib\site-packages\flask\app.py", line 2447, in wsgi_app
    response = self.full_dispatch_request()
  File "C:\Users\Larry\anaconda3\lib\site-packages\flask\app.py", line 1952, in full_dispatch_request
    rv = self.handle_user_exception(e)
  File "C:\Users\Larry\anaconda3\lib\site-packages\flask\app.py", line 1821, in handle_user_exception
    reraise(exc_type, exc_value, tb)
  File "C:\Users\Larry\anaconda3\lib\site-packages\flask\_compat.py", line 39, in reraise
    raise value
  File "C:\Users\Larry\anaconda3\lib\site-packages\flask\app.py", line 1950, in full_dispatch_request
    rv = self.dispatch_request()
  File "C:\Users\Larry\anaconda3\lib\site-packages\flask\app.py", line 1936, in dispatch_request
    return self.view_functions[rule.endpoint](**req.view_args)
  File "C:\Users\Larry\ALX_FULLSTACK\Fyyur\FSND\projects\01_fyyur\starter_code\app.py", line 257, in venues
    #       num_upcoming_shows should be aggregated based on number of upcoming shows per venue.
  File "C:\Users\Larry\anaconda3\lib\site-packages\sqlalchemy\orm\query.py", line 2712, in all
    return self._iter().all()
  File "C:\Users\Larry\anaconda3\lib\site-packages\sqlalchemy\orm\query.py", line 2847, in _iter
    result = self.session.execute(
  File "C:\Users\Larry\anaconda3\lib\site-packages\sqlalchemy\orm\session.py", line 1689, in execute
    result = conn._execute_20(statement, params or {}, execution_options)
  File "C:\Users\Larry\anaconda3\lib\site-packages\sqlalchemy\engine\base.py", line 1583, in _execute_20
    return meth(self, args_10style, kwargs_10style, execution_options)
  File "C:\Users\Larry\anaconda3\lib\site-packages\sqlalchemy\sql\elements.py", line 323, in _execute_on_connection
    return connection._execute_clauseelement(
  File "C:\Users\Larry\anaconda3\lib\site-packages\sqlalchemy\engine\base.py", line 1452, in _execute_clauseelement
    ret = self._execute_context(
  File "C:\Users\Larry\anaconda3\lib\site-packages\sqlalchemy\engine\base.py", line 1814, in _execute_context
    self._handle_dbapi_exception(
  File "C:\Users\Larry\anaconda3\lib\site-packages\sqlalchemy\engine\base.py", line 1995, in _handle_dbapi_exception
    util.raise_(
  File "C:\Users\Larry\anaconda3\lib\site-packages\sqlalchemy\util\compat.py", line 207, in raise_
    raise exception
  File "C:\Users\Larry\anaconda3\lib\site-packages\sqlalchemy\engine\base.py", line 1771, in _execute_context
    self.dialect.do_execute(
  File "C:\Users\Larry\anaconda3\lib\site-packages\sqlalchemy\engine\default.py", line 717, in do_execute
    cursor.execute(statement, parameters)
sqlalchemy.exc.OperationalError: (sqlite3.OperationalError) no such table: Venue
[SQL: SELECT "Venue".id AS "Venue_id", "Venue".name AS "Venue_name", "Venue".city AS "Venue_city", "Venue".state AS "Venue_state", "Venue".address AS "Venue_address", "Venue".phone AS "Venue_phone", "Venue".image_link AS "Venue_image_link", "Venue".facebook_link AS "Venue_facebook_link", "Venue".description AS "Venue_description", "Venue".seeking_talent AS "Venue_seeking_talent", "Venue".website AS "Venue_website", "Venue".genres AS "Venue_genres" 
FROM "Venue" GROUP BY "Venue".id, "Venue".state, "Venue".city]
(Background on this error at: https://sqlalche.me/e/14/e3q8)
